#VRML_SIM R2023b utf8

EXTERNPROTO "https://raw.githubusercontent.com/cyberbotics/webots/R2023b/projects/objects/backgrounds/protos/TexturedBackground.proto"
EXTERNPROTO "https://raw.githubusercontent.com/cyberbotics/webots/R2023b/projects/objects/backgrounds/protos/TexturedBackgroundLight.proto"
EXTERNPROTO "https://raw.githubusercontent.com/cyberbotics/webots/R2023b/projects/objects/floors/protos/RectangleArena.proto"

WorldInfo {
}
Viewpoint {
  orientation -0.32730664950095556 0.3604312365867326 0.8734756326795943 1.60966653012283
  position -0.408227532341093 -7.216605670296964 4.707246747148011
}
TexturedBackground {
}
TexturedBackgroundLight {
}
RectangleArena {
  floorSize 6 7
}
DEF ROBOT Robot {
  translation 0.09257651788962837 -1.972678605261608 0.039471399451226956
  rotation 0.999731915286195 -0.015940686848343228 -0.01679261924177948 1.5711005209410327
  children [
    DEF HINGE_COVER Solid {
      translation 0 0.03 -3.469446951953614e-18
      rotation 0 1 0 -1.5707953071795862
      children [
        Shape {
          appearance PBRAppearance {
            baseColor 0 0.6509803921568628 1
          }
          geometry Box {
            size 0.030000000000000002 0.019999999999999997 0.05
          }
        }
      ]
      name "hingeCover"
    }
    DEF BODY Shape {
      appearance PBRAppearance {
        baseColor 0.917647 0.145098 0.145098
        roughness 1
        metalness 0
      }
      geometry Box {
        size 0.2 0.05 0.08
      }
    }
    DEF WHEEL1 HingeJoint {
      jointParameters HingeJointParameters {
        position -25937.76197049255
        axis 0 0 1
        anchor 0.06 0 0.05
      }
      device [
        RotationalMotor {
          name "wheel1"
        }
      ]
      endPoint Solid {
        translation 0.060010071324414195 8.885043735261581e-06 0.050000010543824816
        rotation 1.767092318482182e-08 -4.192625930253737e-08 0.999999999999999 0.797777587791215
        children [
          DEF WHEEL Shape {
            appearance PBRAppearance {
              baseColor 0.305882 0.898039 0.25098
              roughness 1
              metalness 0
            }
            geometry Cylinder {
              height 0.02
              radius 0.04
              subdivision 24
            }
          }
        ]
        boundingObject USE WHEEL
        physics Physics {
        }
        linearVelocity -0.1347509737077112 0.006462373924541475 -0.002628514058932974
        angularVelocity -0.16159239226265323 -4.952763532827587 -1.6903758648252137e-05
      }
    }
    DEF WHEEL2 HingeJoint {
      jointParameters HingeJointParameters {
        position -25937.67378192782
        axis 0 0 1
        anchor -0.06 0 0.05
      }
      device [
        RotationalMotor {
          name "wheel2"
        }
      ]
      endPoint Solid {
        translation -0.06000036710654964 1.2831686112321726e-06 0.05000000952472374
        rotation 1.7609523273201465e-08 -3.7117876288131156e-08 0.9999999999999992 0.885966066500956
        children [
          USE WHEEL
        ]
        name "solid(1)"
        boundingObject USE WHEEL
        physics Physics {
        }
        linearVelocity -0.13471857965990697 0.006462509138896213 0.0025655890027489812
        angularVelocity -0.16159240282723167 -4.952763864824605 -1.6903794928912132e-05
      }
    }
    DEF WHEEL3 HingeJoint {
      jointParameters HingeJointParameters {
        position -25937.76185183187
        axis 0 0 1
        anchor 0.06 0 -0.05
      }
      device [
        RotationalMotor {
          name "wheel3"
        }
      ]
      endPoint Solid {
        translation 0.06001006958831937 8.886751027961752e-06 -0.05000000738328558
        rotation -1.7671225502077935e-08 4.192000384813852e-08 0.999999999999999 0.7978962484736103
        children [
          USE WHEEL
        ]
        name "solid(2)"
        boundingObject USE WHEEL
        physics Physics {
        }
        linearVelocity -0.1347499927806518 0.0064623637987592025 -0.002568203768056672
        angularVelocity -0.16159239138418666 -4.952763532986873 -1.6903788659716178e-05
      }
    }
    DEF WHEEL4 HingeJoint {
      jointParameters HingeJointParameters {
        position -25937.673634112387
        axis 0 0 1
        anchor -0.06 0 -0.05
      }
      device [
        RotationalMotor {
          name "wheel4"
        }
      ]
      endPoint Solid {
        translation -0.06000036802061397 1.283564723279628e-06 -0.05000000839401549
        rotation -1.7609877817193185e-08 3.71115398466415e-08 0.9999999999999991 0.8861138819345312
        children [
          USE WHEEL
        ]
        name "solid(3)"
        boundingObject USE WHEEL
        physics Physics {
        }
        linearVelocity -0.13471759356352747 0.006462498954678398 0.0026259026923046184
        angularVelocity -0.16159240194625607 -4.952763864993612 -1.6903824164435378e-05
      }
    }
    DEF POLE HingeJoint {
      jointParameters HingeJointParameters {
        position 0.0068548111429938535
        axis 0 0 1
        anchor 0 0.03000000000047226 0
        minStop -1.3
        maxStop 1.3
      }
      device [
        DEF POLE_POS_SENSOR PositionSensor {
          name "polePosSensor"
        }
      ]
      endPoint Solid {
        translation -0.0038929262485308353 0.5299888212033494 -5.369584240405452e-07
        rotation -0.5743490324970277 -0.5788448407672313 0.5788452635954505 2.098901346027397
        children [
          DEF POLE_ENDPOINT Solid {
            translation 0.5000000000000002 0 0
            children [
              DEF BALL Shape {
                appearance PBRAppearance {
                  baseColor 0.03137254901960784 0.047058823529411764 1
                  metalness 0
                }
                geometry Sphere {
                  radius 0.1
                }
              }
            ]
            boundingObject USE BALL
            physics Physics {
              density -1
              mass 0.02
            }
          }
          DEF POLE Shape {
            appearance PBRAppearance {
              baseColor 1 0.1568627450980392 0.1568627450980392
              roughness 1
              metalness 0
            }
            geometry Box {
              size 1 0.020000000000000004 0.019999999999999997
            }
          }
        ]
        name "pole"
        boundingObject USE POLE
        physics Physics {
          density -1
          mass 0.2
        }
        linearVelocity -0.034087939063273384 0.002811508564126967 0.0006577358334693077
        angularVelocity 0.006573764510785528 0.18192055763253784 -9.68527617225178e-06
      }
    }
  ]
  boundingObject USE BODY
  physics Physics {
    density -1
    mass 2
  }
  controller "robot_supervisor_controller"
  supervisor TRUE
  linearVelocity -0.13465255787327102 0.006459420267273784 -2.6882452267955828e-05
  angularVelocity 0.0020747883777318277 0.04455406446858071 -9.577650352201203e-06
}
