#VRML_SIM R2023b utf8

EXTERNPROTO "https://raw.githubusercontent.com/cyberbotics/webots/R2023b/projects/objects/backgrounds/protos/TexturedBackground.proto"
EXTERNPROTO "https://raw.githubusercontent.com/cyberbotics/webots/R2023b/projects/objects/backgrounds/protos/TexturedBackgroundLight.proto"
EXTERNPROTO "https://raw.githubusercontent.com/cyberbotics/webots/R2023b/projects/objects/floors/protos/RectangleArena.proto"

WorldInfo {
}
Viewpoint {
  orientation -0.2528562466679153 0.26582802134873335 0.9302683384845643 1.593059440262344
  position -0.36187075201939056 -6.652441771026875 3.5946341848126413
}
TexturedBackground {
}
TexturedBackgroundLight {
}
RectangleArena {
  floorSize 6 7
}
DEF ROBOT Robot {
  translation -0.17263497135203973 -2.4904785526655506 0.03947799283119494
  rotation 0.9954334034464817 -0.06784901169962579 -0.06714797773826274 1.5752241093900121
  children [
    DEF HINGE_COVER Solid {
      translation 0 0.03 -3.469446951953614e-18
      rotation 0 1 0 -1.5707953071795862
      children [
        Shape {
          appearance PBRAppearance {
            baseColor 0 0.6509803921568628 1
          }
          geometry Box {
            size 0.030000000000000002 0.019999999999999997 0.05
          }
        }
      ]
      name "hingeCover"
    }
    DEF BODY Shape {
      appearance PBRAppearance {
        baseColor 0.917647 0.145098 0.145098
        roughness 1
        metalness 0
      }
      geometry Box {
        size 0.2 0.05 0.08
      }
    }
    DEF WHEEL1 HingeJoint {
      jointParameters HingeJointParameters {
        position -26240.322971938112
        axis 0 0 1
        anchor 0.06 0 0.05
      }
      device [
        RotationalMotor {
          name "wheel1"
        }
      ]
      endPoint Solid {
        translation 0.06001302865671588 -3.260319280472611e-06 0.050000010543824816
        rotation -1.767255671073001e-08 -2.069927352646998e-07 -0.9999999999999785 0.17032911315013582
        children [
          DEF WHEEL Shape {
            appearance PBRAppearance {
              baseColor 0.305882 0.898039 0.25098
              roughness 1
              metalness 0
            }
            geometry Cylinder {
              height 0.02
              radius 0.04
              subdivision 24
            }
          }
        ]
        boundingObject USE WHEEL
        physics Physics {
        }
        linearVelocity 0.137603337828954 -0.026636483046593135 0.0028057577389736348
        angularVelocity 0.6660340351131924 4.909082408004797 -0.00016961954046368707
      }
    }
    DEF WHEEL2 HingeJoint {
      jointParameters HingeJointParameters {
        position -26240.228519384247
        axis 0 0 1
        anchor -0.06 0 0.05
      }
      device [
        RotationalMotor {
          name "wheel2"
        }
      ]
      endPoint Solid {
        translation -0.05999915747321099 1.0351026583878904e-06 0.05000000952472374
        rotation -1.761288177761632e-08 -4.6394560610849096e-07 -0.9999999999998923 0.07587664530498538
        children [
          USE WHEEL
        ]
        name "solid(1)"
        boundingObject USE WHEEL
        physics Physics {
        }
        linearVelocity 0.13761978174614553 -0.02663568448868824 -0.0025387859700480215
        angularVelocity 0.6660339512948436 4.909082085456431 -0.00016962414685499442
      }
    }
    DEF WHEEL3 HingeJoint {
      jointParameters HingeJointParameters {
        position -26240.32271784413
        axis 0 0 1
        anchor 0.06 0 -0.05
      }
      device [
        RotationalMotor {
          name "wheel3"
        }
      ]
      endPoint Solid {
        translation 0.06001302952019581 -3.2561566638333596e-06 -0.05000000738328558
        rotation 1.7672811590474686e-08 2.073069373996707e-07 -0.9999999999999784 0.17007501916587
        children [
          USE WHEEL
        ]
        name "solid(2)"
        boundingObject USE WHEEL
        physics Physics {
        }
        linearVelocity 0.13760765581078696 -0.026636644252958645 0.00253751591078523
        angularVelocity 0.6660340491740365 4.9090823825524 -0.00016961921598020418
      }
    }
    DEF WHEEL4 HingeJoint {
      jointParameters HingeJointParameters {
        position -26240.228224221857
        axis 0 0 1
        anchor -0.06 0 -0.05
      }
      device [
        RotationalMotor {
          name "wheel4"
        }
      ]
      endPoint Solid {
        translation -0.05999915782382724 1.0362031001285853e-06 -0.05000000839401549
        rotation 1.7613244104743785e-08 4.6576852071899036e-07 -0.9999999999998914 0.07558148291529411
        children [
          USE WHEEL
        ]
        name "solid(3)"
        boundingObject USE WHEEL
        physics Physics {
        }
        linearVelocity 0.13762406833421179 -0.02663584512615485 -0.0028070231623932157
        angularVelocity 0.6660339653985637 4.909082060051224 -0.00016962480132096672
      }
    }
    DEF POLE HingeJoint {
      jointParameters HingeJointParameters {
        position 0.0003396631295334478
        axis 0 0 1
        anchor 0 0.03000000000047226 0
        minStop -1.3
        maxStop 1.3
      }
      device [
        DEF POLE_POS_SENSOR PositionSensor {
          name "polePosSensor"
        }
      ]
      endPoint Solid {
        translation -0.00048329903613630724 0.5569756051532191 2.329729554228643e-05
        rotation -0.5799301004972435 -0.5760558075972879 0.5760562342954839 2.0905282115323827
        children [
          DEF POLE_ENDPOINT Solid {
            translation 0.5000000000000002 0 0
            children [
              DEF BALL Shape {
                appearance PBRAppearance {
                  baseColor 0.03137254901960784 0.047058823529411764 1
                  metalness 0
                }
                geometry Sphere {
                  radius 0.1
                }
              }
            ]
            boundingObject USE BALL
            physics Physics {
              density -1
              mass 0.02
            }
          }
          DEF POLE Shape {
            appearance PBRAppearance {
              baseColor 1 0.1568627450980392 0.1568627450980392
              roughness 1
              metalness 0
            }
            geometry Box {
              size 1 0.020000000000000004 0.019999999999999997
            }
          }
        ]
        name "pole"
        boundingObject USE POLE
        physics Physics {
          density -1
          mass 0.2
        }
        linearVelocity 0.029197133493237208 -0.010200976283313153 7.923896363626188e-05
        angularVelocity -0.02822651849779103 -0.18692372894902887 -2.8988285542784134e-05
      }
    }
  ]
  boundingObject USE BODY
  physics Physics {
    density -1
    mass 2
  }
  controller "robot_supervisor_controller"
  supervisor TRUE
  linearVelocity 0.1375560919833146 -0.02662701260296723 3.3655832044132746e-05
  angularVelocity -0.008912192819659319 -0.04515020673151795 -3.241173592939213e-05
}
